<?xml version="1.0" ?>
<sdf version="1.5">
     <model name='jetbot'>

      <link name='chassis'>
        <pose>0 0 0 0 0 0</pose>
        <inertial>
          <mass>1.14395</mass>
          <inertia>
            <ixx>0.126164</ixx>
            <ixy>0</ixy>
            <ixz>0</ixz>
            <iyy>0.416519</iyy>
            <iyz>0</iyz>
            <izz>0.481014</izz>
          </inertia>
        </inertial>
        <visual name='visual'>
          <geometry>
            <box>
              <size>0.5 0.3 0.1</size>
            </box>
          </geometry>
          <material>
            <ambient>0.4 0.4 0.4 1</ambient>
            <diffuse>0.5 0.5 0.5 1</diffuse>
          </material>
        </visual>
        <collision name='collision'>
          <geometry>
            <box>
              <size>0.5 0.3 0.1</size>
            </box>
          </geometry>
        </collision>
      </link>
      
      <link name='cover'>
        <pose>-0.05 0 0.125 0 -0 0</pose>
        <inertial>
          <mass>1.14395</mass>
          <inertia>
            <ixx>0.126164</ixx>
            <ixy>0</ixy>
            <ixz>0</ixz>
            <iyy>0.416519</iyy>
            <iyz>0</iyz>
            <izz>0.481014</izz>
          </inertia>
        </inertial>
        <visual name='visual'>
          <geometry>
            <box>
              <size>0.4 0.25 0.15</size>
            </box>
          </geometry>
          <material>
            <ambient>0 1 0 1</ambient>
            <diffuse>0 1 0 1</diffuse>
          </material>
        </visual>
        <collision name='collision'>
          <geometry>
            <box>
              <size>0.4 0.25 0.15</size>
            </box>
          </geometry>
        </collision>
      </link>

      <link name='left_wheel'>
        <pose>0.2 0.175 0.0 -1.5707 0 0</pose>
        <inertial>
          <mass>2</mass>
          <inertia>
            <ixx>0.145833</ixx>
            <ixy>0</ixy>
            <ixz>0</ixz>
            <iyy>0.145833</iyy>
            <iyz>0</iyz>
            <izz>0.125</izz>
          </inertia>
        </inertial>
        <visual name='visual'>
          <geometry>
            <cylinder>
              <length>0.05</length>
              <radius>0.1</radius>
            </cylinder>
          </geometry>
          <material>
            <ambient>0 0 0 1</ambient>
            <diffuse>0.3 0.3 0.3 1</diffuse>
          </material>
        </visual>
        <collision name='collision'>
          <geometry>
            <cylinder>
              <length>0.05</length>
              <radius>0.1</radius>
            </cylinder>
          </geometry>
          <surface>
            <friction>
              <ode>
                <mu>1</mu>
                <mu2>1</mu2>
                <slip1>0</slip1>
                <slip2>0</slip2>
              </ode>
            </friction>
            <contact>
              <ode>
                <soft_cfm>0</soft_cfm>
                <soft_erp>0.2</soft_erp>
                <kp>1e+13</kp>
                <kd>1</kd>
                <max_vel>0.01</max_vel>
                <min_depth>0.01</min_depth>
              </ode>
            </contact>
          </surface>
        </collision>
      </link>

      <link name='right_wheel'>
        <pose>0.2 -0.175 0.0 -1.5707 0 0</pose>
        <inertial>
          <mass>2</mass>
          <inertia>
            <ixx>0.145833</ixx>
            <ixy>0</ixy>
            <ixz>0</ixz>
            <iyy>0.145833</iyy>
            <iyz>0</iyz>
            <izz>0.125</izz>
          </inertia>
        </inertial>
        <visual name='visual'>
          <geometry>
            <cylinder>
              <length>0.05</length>
              <radius>0.1</radius>
            </cylinder>
          </geometry>
          <material>
            <ambient>0 0 0 1</ambient>
            <diffuse>0.3 0.3 0.3 1</diffuse>
          </material>
        </visual>
        <collision name='collision'>
          <geometry>
            <cylinder>
              <length>0.05</length>
              <radius>0.1</radius>
            </cylinder>
          </geometry>
          <surface>
            <friction>
              <ode>
                <mu>1</mu>
                <mu2>1</mu2>
                <slip1>0</slip1>
                <slip2>0</slip2>
              </ode>
            </friction>
            <contact>
              <ode>
                <soft_cfm>0</soft_cfm>
                <soft_erp>0.2</soft_erp>
                <kp>1e+13</kp>
                <kd>1</kd>
                <max_vel>0.01</max_vel>
                <min_depth>0.01</min_depth>
              </ode>
            </contact>
          </surface>
        </collision>
      </link>

      <link name='caster'>
        <pose>-0.15 -0 -0.05 0 -0 0</pose>
        <inertial>
          <mass>1</mass>
          <inertia>
            <ixx>0.1</ixx>
            <ixy>0</ixy>
            <ixz>0</ixz>
            <iyy>0.1</iyy>
            <iyz>0</iyz>
            <izz>0.1</izz>
          </inertia>
        </inertial>
        <visual name='visual'>
          <geometry>
            <sphere>
              <radius>0.05</radius>
            </sphere>
          </geometry>
          <material>
            <ambient>0 0 0 1</ambient>
            <diffuse>0.3 0.3 0.3 1</diffuse>
          </material>
        </visual>
        <collision name='collision'>
          <geometry>
            <sphere>
              <radius>0.05</radius>
            </sphere>
          </geometry>
        </collision>
      </link>

      <link name="distance_sensor">
        <pose>0.125 0 0.21 0 -0 0</pose>
        <visual name="visual_box">
          <geometry>
            <cylinder>
              <length>0.03</length>
              <radius>0.025</radius>
            </cylinder>
          </geometry>
          <material>
            <ambient>0.7 0.7 0 1</ambient>
            <diffuse>0.7 0.7 0 1</diffuse>
          </material>
        </visual>
        <collision name="collision_box">
          <geometry>
            <cylinder>
              <length>0.05</length>
              <radius>0.05</radius>
            </cylinder>
          </geometry>
          <laser_retro>100.0</laser_retro>
        </collision>

        <!-- ray sensor -->
        <sensor name="sensor_ray_front" type="ray">
          <ray>
            <scan>
              <horizontal>
                <samples>2</samples>
                <resolution>1.0</resolution>
                <min_angle>-0.001</min_angle>
                <max_angle>0.001</max_angle>
              </horizontal>
            </scan>
            <range>
              <min>0.1</min>
              <max>10.0</max>
              <resolution>0.02</resolution>
            </range>
            <noise>
              <type>gaussian</type>
              <mean>0</mean>
              <stddev>0.01</stddev>
            </noise>
          </ray>
          <always_on>true</always_on>
          <update_rate>30.0</update_rate>
          <!--
          <plugin name="laserscan" filename="libgazebo_ros_ray_sensor.so">
            <ros>
              <namespace>/ray_front</namespace>
              <remapping>~/out:=laserscan</remapping>
            </ros>
            <output_type>sensor_msgs/LaserScan</output_type>
          </plugin>
          -->
          <plugin name="range" filename="libgazebo_ros_ray_sensor.so">
            <ros>
              <namespace>/jetbot</namespace>
              <remapping>~/out:=laser_front</remapping>
            </ros>
            <output_type>sensor_msgs/Range</output_type>
          </plugin>
        </sensor>
        
        <sensor name="sensor_ray_side" type="ray">
          <pose>0.125 0 0.225 0 -0 1.5708</pose>
          <ray>
            <scan>
              <horizontal>
                <samples>2</samples>
                <resolution>1.0</resolution>
                <min_angle>-0.001</min_angle>
                <max_angle>0.001</max_angle>
              </horizontal>
            </scan>
            <range>
              <min>0.1</min>
              <max>10.0</max>
              <resolution>0.02</resolution>
            </range>
            <noise>
              <type>gaussian</type>
              <mean>0</mean>
              <stddev>0.01</stddev>
            </noise>
          </ray>
          <always_on>true</always_on>
          <update_rate>30.0</update_rate>
          <plugin name="range" filename="libgazebo_ros_ray_sensor.so">
            <ros>
              <namespace>/jetbot</namespace>
              <remapping>~/out:=laser_side</remapping>
            </ros>
            <output_type>sensor_msgs/Range</output_type>
          </plugin>
        </sensor>
      </link>

      <joint name='left_wheel_joint' type='revolute'>
        <parent>chassis</parent>
        <child>left_wheel</child>
        <axis>
          <xyz>0 0 1</xyz>
          <limit>
            <lower>-1.79769e+308</lower>
            <upper>1.79769e+308</upper>
          </limit>
        </axis>
      </joint>

      <joint name='right_wheel_joint' type='revolute'>
        <parent>chassis</parent>
        <child>right_wheel</child>
        <axis>
          <xyz>0 0 1</xyz>
          <limit>
            <lower>-1.79769e+308</lower>
            <upper>1.79769e+308</upper>
          </limit>
        </axis>
      </joint>

      <joint name='caster_wheel' type='ball'>
        <parent>chassis</parent>
        <child>caster</child>
      </joint>
      
      <joint name='cover_joint' type='fixed'>
        <parent>chassis</parent>
        <child>cover</child>
      </joint>
      
      <joint name='ray_front_joint' type='fixed'>
        <parent>chassis</parent>
        <child>distance_sensor</child>
      </joint>


      <plugin name='diff_drive' filename='libgazebo_ros_diff_drive.so'>

        <ros>
          <namespace>/jetbot</namespace>
        </ros>

        <!-- wheels -->
        <left_joint>left_wheel_joint</left_joint>
        <right_joint>right_wheel_joint</right_joint>

        <!-- kinematics -->
        <wheel_separation>1.25</wheel_separation>
        <wheel_diameter>0.6</wheel_diameter>

        <!-- limits -->
        <max_wheel_torque>20</max_wheel_torque>
        <max_wheel_acceleration>1.0</max_wheel_acceleration>

        <!-- output -->
        <publish_odom>true</publish_odom>
        <publish_odom_tf>true</publish_odom_tf>
        <publish_wheel_tf>true</publish_wheel_tf>

        <odometry_frame>odom_demo</odometry_frame>
        <robot_base_frame>chassis</robot_base_frame>

      </plugin>

    </model>
</sdf>
